Workbook

Sheet Sheet1
B2: ID | C2: NOMBRE | D2: DIRECCION PRINCIPAL | E2: ZONA | F2: CELULAR | G2: DNI | H2: FILTRO
B3: 1 | C3: ELITA TAMANI PACAYA (HENRY FLORES L.) | D3: CARR SUNAMPE NRO. PUERTA 391 B C.P. HUACA GRANDE - SUNAMPE | E3: ZONA: SUNAMPE – SAN IGNACIO | F3: 934500127 | G3: 76044922 | H3: =VLOOKUP(G3,consolidado!$A$2:$B$656,2,FALSE) -> #N/A
B4: 2 | C4: FACHO LOZADA AUGUSTO IGNACIO | D4: AV.PRINCIPAL 543 SUNAMPE LOTE 6A | E4: ZONA: SUNAMPE – SANTA ROSA | F4: 998530990 | G4: 43312934 | H4: =VLOOKUP(G4,consolidado!$A$2:$B$656,2,FALSE) -> #N/A
B5: 3 | C5: BARRUTIA NAPA GERMAN YSAIAS | D5: SUNAMPE PASO DE GOMEZ S/N | E5: ZONA: SUNAMPE – COLEGIO | F5: 979420182 | G5: 40339325 | H5: =VLOOKUP(G5,consolidado!$A$2:$B$656,2,FALSE) -> #N/A
B6: 4 | C6: PEÑA SOTO KATERINNE LIZETH | D6: Calle Nueva Esperanza Mz. A Lt. 12 -Grocio Prado | E6: ZONA: GROCIO - MEJILLONEROS | F6: 936691447 | G6: 47353719 | H6: =VLOOKUP(G6,consolidado!$A$2:$B$656,2,FALSE) -> #N/A
B7: 5 | C7: BEGAZO PEÑALOZA MILAGROS LUCIA | D7: Psj. San Cristobal 360 - Villa Julia | E7: ZONA: SUNAMPE – VILLA JULIA | F7: 925019236 | G7: 21869870 | H7: =VLOOKUP(G7,consolidado!$A$2:$B$656,2,FALSE) -> #N/A
B8: 6 | C8: RIQUELME APOLAYA VDA DE PEREZ GREGORIA ELISA | D8: Av. Melchorita Nº 604 - Grocio Prado | E8: ZONA: GROCIO - MEJILLONEROS | F8: 956698366 | G8: 21782120 | H8: =VLOOKUP(G8,consolidado!$A$2:$B$656,2,FALSE) -> #N/A
B9: 7 | C9: TASAYCO MAGALLANES ALICIA MARIA | D9: PSJ. DOS DE MAYO N°303 - CRUZ BLANCA | E9: ZONA: CRUZ BLANCA PARTE ALTA oruro | F9: 945857289 | G9: 41576648 | H9: =VLOOKUP(G9,consolidado!$A$2:$B$656,2,FALSE) -> #N/A
B10: 8 | C10: CAMPOS VILLA JOHN WILLIAMS | D10: Parada de los Amigos Pasaje Villa - Sunampe | E10: ZONA: SUNAMPE – SAN PILPA | F10: 967061773 | G10: 75347649 | H10: =VLOOKUP(G10,consolidado!$A$2:$B$656,2,FALSE) -> #N/A
B11: 9 | C11: LOYOLA SARAVIA ROBERTO CARLOS | D11: Parada de los Amigos Pasaje Renovacion - Sunampe | E11: ZONA: SUNAMPE – SAN PILPA | F11: 913789112 | G11: 47516353 | H11: =VLOOKUP(G11,consolidado!$A$2:$B$656,2,FALSE) -> #N/A
B12: 10 | C12: PONTE CERNA MARIBEL RUDI | D12: Pasaje Santa Rosa - Espalda de Cruz Blanca | E12: ZONA: CRUZ BLANCA PARTE BAJA | F12: 923757401 | G12: 32872532 | H12: =VLOOKUP(G12,consolidado!$A$2:$B$656,2,FALSE) -> #N/A
B13: 11 | C13: ABREGU NAPA FRANK ENRIQUE | D13: Pasaje Napa - Cruz Blanca | E13: ZONA: CRUZ BLANCA PARTE ALTA oruro | F13: 918104510 | G13: 77564718 | H13: =VLOOKUP(G13,consolidado!$A$2:$B$656,2,FALSE) -> #N/A
B14: 12 | C14: GARCIA CASTILLA MARITZA | D14: Prolongacion Alva Maurtua - Cruz Blanca (Ex toma de cala) | E14: ZONA: CRUZ BLANCA PARTE BAJA | F14: 917631665 | G14: 40231558 | H14: =VLOOKUP(G14,consolidado!$A$2:$B$656,2,FALSE) -> #N/A
B15: 13 | C15: GIRAO ATUNCAR JAVIER ORLANDO | D15: Av. Alfonso Ugarte Mz M Lt 5, CP San Pedro de Pilpa - Sunampe | E15: ZONA: SUNAMPE – SAN PILPA | F15: 987013897 | G15: 42567350 | H15: =VLOOKUP(G15,consolidado!$A$2:$B$656,2,FALSE) -> #N/A
B16: 14 | C16: CHAVEZ MARTINEZ MARTHA MARIA | D16: AV. PARAISO MZ C LT 27, LOMO LARGO - SUNAMPE | E16: ZONA: SUNAMPE – PARAISO | F16: 985 192 082 | G16: 45123518 | H16: =VLOOKUP(G16,consolidado!$A$2:$B$656,2,FALSE) -> #N/A
B17: 15 | C17: TORRES DEL AGUILA DORA ESTHER | D17: Psj 2 de mayo #285-4 cruz Blanca Referencia espalda del colegio 22234 | E17: ZONA: CRUZ BLANCA PARTE ALTA oruro | F17: 991427548 | G17: 41164414 | H17: =VLOOKUP(G17,consolidado!$A$2:$B$656,2,FALSE) -> #N/A
B18: 16 | C18: MAGALLANES ALMEYDA MARIA MIRTHA | D18: AV. ALVA MAURTUA N° 580 - CRUZ BLANCA - CHINCHA ALTA | E18: ZONA: CRUZ BLANCA PARTE ALTA oruro | F18: 922427114 | G18: 21878769 | H18: =VLOOKUP(G18,consolidado!$A$2:$B$656,2,FALSE) -> #N/A
B19: 17 | C19: GARCIA CARBAJAL MILAGRO MELCHORA | D19: barrio el tigre 280 av los proceres chincha | E19: ZONA: CRUZ BLANCA PARTE BAJA | F19: 966242063 | G19: 21862703 | H19: =VLOOKUP(G19,consolidado!$A$2:$B$656,2,FALSE) -> #N/A
B20: 18 | C20: DE LA CRUZ MANRIQUE NOLBERTO FLORECINDO | D20: calle San Vicente Ferrer 520 Sunampe | E20: ZONA: SUNAMPE – SAN PILPA | F20: 938429070 | G20: 21854378 | H20: =VLOOKUP(G20,consolidado!$A$2:$B$656,2,FALSE) -> #N/A
B21: 19 | C21: TORRES TASAYCO CARLOS EDUARDO | D21: PSJE SANTA ROSA Nro. Puerta 128 Cruz Blanca CHINCHA ALTA | E21: ZONA: CRUZ BLANCA PARTE ALTA oruro | F21: 972287862 | G21: 46928659 | H21: =VLOOKUP(G21,consolidado!$A$2:$B$656,2,FALSE) -> #N/A
B22: 20 | C22: ALMEYDA DE NAPA MARGARITA VICTORIA | D22: Av. paraíso - Lomo Largo - Sunampe ref: A 1 cuadra del hostal “El otro Sitio” | E22: ZONA: SUNAMPE – PARAISO | F22: 965189450 | G22: 21848813 | H22: =VLOOKUP(G22,consolidado!$A$2:$B$656,2,FALSE) -> #N/A
B23: 21 | C23: PACHAS DIAZ DAVID ERNESTO | D23: Psj. 2 de mayo - Cruz blanca | E23: ZONA: CRUZ BLANCA PARTE ALTA oruro | F23: 956 022 078 | G23: 46250661 | H23: =VLOOKUP(G23,consolidado!$A$2:$B$656,2,FALSE) -> #N/A
B24: 22 | C24: ESPINOZA MUÑOZ LILIANA LASTENIA | D24: Av. San marcelo 158 (Villa Julia) - Sunampe | E24: ZONA: SUNAMPE – VILLA JULIA | F24: 922393873 | G24: 21854605 | H24: =VLOOKUP(G24,consolidado!$A$2:$B$656,2,FALSE) -> #N/A
B25: 23 | C25: ALMEYDA GARCIA ABEL ARTURO | D25: Calle Grau 108 - Lomo Largo - Sunampe | E25: ZONA: SUNAMPE – PARAISO | F25: 914013935 | G25: 21854743 | H25: =VLOOKUP(G25,consolidado!$A$2:$B$656,2,FALSE) -> #N/A
B26: 24 | C26: MAGALLANES CRISOSTOMO KATHERIN CINTHIA | D26: PSJ DE LA CRUZ MATIAS - LOMO LARGO - SUNAMPE | E26: ZONA: SUNAMPE – PARAISO | F26: 902642312 | G26: 46175442 | H26: =VLOOKUP(G26,consolidado!$A$2:$B$656,2,FALSE) -> #N/A
B27: 25 | C27: GIRAO ATUNCAR LUIS CARLOS | D27: PASAJE SANTA ROSA 130 - 01 SUNAMPE | E27: ZONA: SUNAMPE – SAN PILPA | F27: 923311111 | G27: 47144583 | H27: =VLOOKUP(G27,consolidado!$A$2:$B$656,2,FALSE) -> #N/A
B28: 26 | C28: SARAVIA YATACO ARMANDO FELIX | D28: Psj. Betania interior 04 Nº 390 - Guayabo - Sunampe | E28: ZONA: SUNAMPE – VILLA JULIA | F28: 979645543 | G28: 41971143 | H28: =VLOOKUP(G28,consolidado!$A$2:$B$656,2,FALSE) -> #N/A
B29: 27 | C29: DIAZ MAGALLANES SANTOS MANUEL | D29: CRUZ BLANCA VIRGEN DEL CARMEN | E29: ZONA: CRUZ BLANCA PARTE BAJA | F29: 925064547 | G29: 21797192 | H29: =VLOOKUP(G29,consolidado!$A$2:$B$656,2,FALSE) -> #N/A
B30: 28 | C30: MESIAS GONZALES DIANA FIORELLA | D30: Calle los Próceres Lote 24-Cruz Blanca | E30: ZONA: CRUZ BLANCA PARTE BAJA | F30: 960544540 | G30: 45082671 | H30: =VLOOKUP(G30,consolidado!$A$2:$B$656,2,FALSE) -> #N/A
B31: 29 | C31: SARAVIA BENDEZU LUIS RICHARD | D31: Toma de cala Cruz blanca -. Virgen de carmen | E31: ZONA: CRUZ BLANCA PARTE BAJA | F31: 975537912 | G31: 21869687 | H31: =VLOOKUP(G31,consolidado!$A$2:$B$656,2,FALSE) -> #N/A
B32: 30 | C32: CONTRERAS ENRIQUEZ CARLOS JAVIER | D32: SANTA FE calle primavera lomo largo 441 | E32: ZONA: SUNAMPE – SANTA FE | F32: 956118797 | G32: 21877560 | H32: =VLOOKUP(G32,consolidado!$A$2:$B$656,2,FALSE) -> #N/A
B33: 31 | C33: TORRES ROMAN KATHERINE MILAGROS | D33: Av. Huascar 130 San IGNACIO | E33: ZONA: SUNAMPE – SAN IGNACIO | F33: 938358973 | G33: 46294714 | H33: =VLOOKUP(G33,consolidado!$A$2:$B$656,2,FALSE) -> #N/A
B34: 32 | C34: TASAYCO GARCIA DANIEL | D34: Av San Francisco 117 sunampe | E34: ZONA: SUNAMPE – SAN IGNACIO | F34: 922771211 | G34: 21845817 | H34: =VLOOKUP(G34,consolidado!$A$2:$B$656,2,FALSE) -> #N/A
B35: 33 | C35: ABURTO DE LA CRUZ CARMEN ROSA | D35: SAN IGANCIO PASANDO Cevicheria de san ignacio | E35: ZONA: SUNAMPE – SAN IGNACIO | F35: 936972485 | G35: 41615897 | H35: =VLOOKUP(G35,consolidado!$A$2:$B$656,2,FALSE) -> #N/A
... B41: 39 | C41: LAZARO CANCHARI NESTOR BALVIS | D41: C.P. CONDORILLO ALTO MZ L LT 10 - CHINCHA | E41: ZONA: CONDORILLO PARTE ALTA | F41: 910925866 | G41: 21856980 | H41: =VLOOKUP(G41,consolidado!$A$2:$B$656,2,FALSE) -> #N/A
B42: 40 | C42: CARBAJAL NAVARRO CRISTHIAN JUNIOR | D42: Av. Alva Maurtua S/N - Cruz Blanca | E42: ZONA: CRUZ BLANCA PARTE ALTA oruro | F42: 924 343 517 | G42: 76564222 | H42: =VLOOKUP(G42,consolidado!$A$2:$B$656,2,FALSE) -> #N/A
B43: 41 | C43: SOTELO MATTA GUISELLA ESPERANZA | D43: PSJ. ANDRES AVELINO CACERES 137, SANTA ROSA - SUNAMPE | E43: ZONA: SUNAMPE – SANTA ROSA | F43: 929 564 075 | G43: 70401928 | H43: =VLOOKUP(G43,consolidado!$A$2:$B$656,2,FALSE) -> #N/A
B44: 42 | C44: CHAVEZ YATACO JESUS ALBERTO | D44: Psj. Santa Rosa S/N - Cruz Blanca | E44: ZONA: CRUZ BLANCA CAMPO | F44: 921159983 | G44: 43350897 | H44: =VLOOKUP(G44,consolidado!$A$2:$B$656,2,FALSE) -> #N/A
B45: 43 | C45: PAEZ SOTELO HELLEN VICTORIA | D45: Calle San Antonio 301 - Sunampe | E45: ZONA: SUNAMPE – SAN IGNACIO | F45: 991881274 | G45: 43073315 | H45: =VLOOKUP(G45,consolidado!$A$2:$B$656,2,FALSE) -> #N/A
B46: 44 | C46: GARCIA GARIBAY EMILIA MELCHORITA | D46: C.P. CONDORILLO ALTO, CRUZ DEL ROSARIO MZ A LT 12 - CHINCHA | E46: ZONA: CONDORILLO PARTE ALTA | F46: 977207233 | G46: 43081077 | H46: =VLOOKUP(G46,consolidado!$A$2:$B$656,2,FALSE) -> #N/A
...

Sheet consolidado
A1: # | B1: CLIENTE | C1: DIRECCIÓN | D1: DISTRITO | E1: ZONA | F1: TELÉFONO | G1: DNI | H1: TIPO
A2: 1 | B2: HUATTA HUATTA FRANCISCO FABIO | C2: AAHH Señor de los Milagros Mz p1 L 16, Quinta etapa | D2: PUEBLO NUEVO | E2: Zona: SrMilagros | F2: 941778098 | G2: 01248667 | H2: F2 | I2: ="('"&B2&"','"&C2&"','"&D2&"','"&E2&"','"&F2&"','"&G2&"','"&H2&"')," -> ('HUATTA HUATTA FRANCISCO FABIO','AAHH Señor de los Milagros Mz p1 L 16, Quinta etapa','PUEBLO NUEVO','Zona: SrMilagros','941778098','01248667','F2'),
A3: 2 | B3: FLOR DEL VALLE RODRIGUEZ GARELLI | C3: Av. alva maurtua lt 05 Cruz Blanca | D3: CHINCHA ALTA | E3: ZONA: CRUZ BLANCA PARTE ALTA oruro | F3: 917638838 | G3: 004039538 | H3: F1 | I3: ="('"&B3&"','"&C3&"','"&D3&"','"&E3&"','"&F3&"','"&G3&"','"&H3&"')," -> ('FLOR DEL VALLE RODRIGUEZ GARELLI','Av. alva maurtua lt 05 Cruz Blanca','CHINCHA ALTA','ZONA: CRUZ BLANCA PARTE ALTA oruro','917638838','004039538','F1'),
A4: 3 | B4: TIMAURE CAMACHO CAROLINA COROMOTO | C4: CL. Santa Teresa 355 Entrada a Sant aFe- Sunampe | D4: SUNAMPE | E4: ZONA: SUNAMPE – SANTA FE | F4: 902253434 | G4: 004377762 | H4: F1 | I4: ="('"&B4&"','"&C4&"','"&D4&"','"&E4&"','"&F4&"','"&G4&"','"&H4&"')," -> ('TIMAURE CAMACHO CAROLINA COROMOTO','CL. Santa Teresa 355 Entrada a Sant aFe- Sunampe','SUNAMPE','ZONA: SUNAMPE – SANTA FE','902253434','004377762','F1'),
A5: 4 | B5: YATACO VIDAL JAIME JUAN | C5: Calle Parada de los amigos 409 - Sunampe | D5: SUNAMPE | E5: ZONA: SUNAMPE – SAN PILPA | F5: 989058641 | G5: 06093318 | H5: F1 | I5: ="('"&B5&"','"&C5&"','"&D5&"','"&E5&"','"&F5&"','"&G5&"','"&H5&"')," -> ('YATACO VIDAL JAIME JUAN','Calle Parada de los amigos 409 - Sunampe','SUNAMPE','ZONA: SUNAMPE – SAN PILPA','989058641','06093318','F1'),
A6: 6 | B6: JANAMPA GOMEZ MAXIMO | C6: Condorillo alto MZ I LT 01 | D6: CHINCHA ALTA | E6: ZONA: CRUZ BLANCA CAMPO | F6: 902102201 | G6: 06567453 | H6: F1 | I6: ="('"&B6&"','"&C6&"','"&D6&"','"&E6&"','"&F6&"','"&G6&"','"&H6&"')," -> ('JANAMPA GOMEZ MAXIMO','Condorillo alto MZ I LT 01','CHINCHA ALTA','ZONA: CRUZ BLANCA CAMPO','902102201','06567453','F1'),
A7: 7 | B7: DE LA CRUZ QUISPE LILIANA | C7: Calle las Nazarenas, S/n Huaca Grande- Sunampe | D7: SUNAMPE | E7: ZONA: SUNAMPE – HUACA GRANDE | F7: 977265651 | G7: 06799544 | H7: F1 | I7: ="('"&B7&"','"&C7&"','"&D7&"','"&E7&"','"&F7&"','"&G7&"','"&H7&"')," -> ('DE LA CRUZ QUISPE LILIANA','Calle las Nazarenas, S/n Huaca Grande- Sunampe','SUNAMPE','ZONA: SUNAMPE – HUACA GRANDE','977265651','06799544','F1'),
A8: 8 | B8: LEVANO DE LA CRUZ FRANCISCA ESTHER | C8: AV. SANTA RITA N°204 (AMERICA) - CHINCHA ALTA | D8: CHINCHA ALTA | E8: ZONA: CHINCHA - PROGRESO | F8: 956 505 830 | G8: 07597465 | H8: F2 | I8: ="('"&B8&"','"&C8&"','"&D8&"','"&E8&"','"&F8&"','"&G8&"','"&H8&"')," -> ('LEVANO DE LA CRUZ FRANCISCA ESTHER','AV. SANTA RITA N°204 (AMERICA) - CHINCHA ALTA','CHINCHA ALTA','ZONA: CHINCHA - PROGRESO','956 505 830','07597465','F2'),
A9: 9 | B9: CONOCC HUAMAN MANUEL MARINO | C9: PSJ. LA PALMA, FUNDO EL NISPERO LT. 05 - SUNAMPE | D9: SUNAMPE | E9: ZONA: SUNAMPE – SAN PILPA | F9: 945 301 046 | G9: 08347575 | H9: F1 | I9: ="('"&B9&"','"&C9&"','"&D9&"','"&E9&"','"&F9&"','"&G9&"','"&H9&"')," -> ('CONOCC HUAMAN MANUEL MARINO','PSJ. LA PALMA, FUNDO EL NISPERO LT. 05 - SUNAMPE','SUNAMPE','ZONA: SUNAMPE – SAN PILPA','945 301 046','08347575','F1'),
A10: 10 | B10: VIOLETA GUTIERREZ GUILLERMO FELICIANO | C10: Av. pachacutec 2645 Cruz Blanca | D10: CHINCHA ALTA | E10: ZONA: CRUZ BLANCA VIRGEN CARMEN | F10: 997588370 | G10: 08998598 | H10: F1 | I10: ="('"&B10&"','"&C10&"','"&D10&"','"&E10&"','"&F10&"','"&G10&"','"&H10&"')," -> ('VIOLETA GUTIERREZ GUILLERMO FELICIANO','Av. pachacutec 2645 Cruz Blanca','CHINCHA ALTA','ZONA: CRUZ BLANCA VIRGEN CARMEN','997588370','08998598','F1'),
A11: 11 | B11: PRIETO LOYOLA REYNALDO | C11: San Juan con San pedro de pilpa - Sunampe | D11: SUNAMPE | E11: ZONA: SUNAMPE – SAN PILPA | F11: 941310699 | G11: 09267192 | H11: F1 | I11: ="('"&B11&"','"&C11&"','"&D11&"','"&E11&"','"&F11&"','"&G11&"','"&H11&"')," -> ('PRIETO LOYOLA REYNALDO','San Juan con San pedro de pilpa - Sunampe','SUNAMPE','ZONA: SUNAMPE – SAN PILPA','941310699','09267192','F1'),
A12: 12 | B12: ARANGO ESCOBAR TEOFILO GENARO | C12: Satelite primaveral, quinta etapa ref: conocido como Hugo Chavez | D12: PUEBLO NUEVO | E12: Zona: SrMilagros | F12: 995719091 | G12: 09436528 | H12: F1 | I12: ="('"&B12&"','"&C12&"','"&D12&"','"&E12&"','"&F12&"','"&G12&"','"&H12&"')," -> ('ARANGO ESCOBAR TEOFILO GENARO','Satelite primaveral, quinta etapa ref: conocido como Hugo Chavez','PUEBLO NUEVO','Zona: SrMilagros','995719091','09436528','F1'),
A13: 14 | B13: BENITES BOCANEGRA FRANCISCO HERMAN | C13: PSJ. SAN JUAN LT. 94A - ALFONSO UGARTE - SUNAMPE | D13: SUNAMPE | E13: ZONA: SUNAMPE – SAN PILPA | F13: 993656810 | G13: 09736546 | H13: F1 | I13: ="('"&B13&"','"&C13&"','"&D13&"','"&E13&"','"&F13&"','"&G13&"','"&H13&"')," -> ('BENITES BOCANEGRA FRANCISCO HERMAN','PSJ. SAN JUAN LT. 94A - ALFONSO UGARTE - SUNAMPE','SUNAMPE','ZONA: SUNAMPE – SAN PILPA','993656810','09736546','F1'),
A14: 15 | B14: RAMOS RIOS MOISES MATEO | C14: Pazo de gomez santa rosa , segunda entrada | D14: SUNAMPE | E14: Zona: Sunampe | F14: 960106705 | G14: 09756783 | H14: F1 | I14: ="('"&B14&"','"&C14&"','"&D14&"','"&E14&"','"&F14&"','"&G14&"','"&H14&"')," -> ('RAMOS RIOS MOISES MATEO','Pazo de gomez santa rosa , segunda entrada','SUNAMPE','Zona: Sunampe','960106705','09756783','F1'),
A15: 16 | B15: ROMERO GARRIAZO JOSE ALBERTO | C15: PSJ. SARAVIA S/N - CERCADO DE GROCIO PRADO | D15: SUNAMPE | E15: ZONA: SUNAMPE – SAN PILPA | F15: 981295133 | G15: 15359111 | H15: F1 | I15: ="('"&B15&"','"&C15&"','"&D15&"','"&E15&"','"&F15&"','"&G15&"','"&H15&"')," -> ('ROMERO GARRIAZO JOSE ALBERTO','PSJ. SARAVIA S/N - CERCADO DE GROCIO PRADO','SUNAMPE','ZONA: SUNAMPE – SAN PILPA','981295133','15359111','F1'),
A16: 17 | B16: PALLIN HUARCAYA CARLOS AURELIO | C16: PSJ. VILLA S/N, CALLE SAN VICENTE DE FERRER - SUNAMPE | D16: SUNAMPE | E16: ZONA: SUNAMPE – SAN PILPA | F16: 918 102 342 | G16: 15359608 | H16: F1 | I16: ="('"&B16&"','"&C16&"','"&D16&"','"&E16&"','"&F16&"','"&G16&"','"&H16&"')," -> ('PALLIN HUARCAYA CARLOS AURELIO','PSJ. VILLA S/N, CALLE SAN VICENTE DE FERRER - SUNAMPE','SUNAMPE','ZONA: SUNAMPE – SAN PILPA','918 102 342','15359608','F1'),
A17: 18 | B17: CAMPOS BARRIOS JUANA MILAGROS | C17: UPIS SAN ANDRES MZ. F - LT. 19 - PUEBLO NUEVO - CHINCHA | D17: PUEBLO NUEVO | E17: ZONA: PUEBLO - TECHO PROPIO | F17: 956 517 578 | G17: 15439628 | H17: F1 | I17: ="('"&B17&"','"&C17&"','"&D17&"','"&E17&"','"&F17&"','"&G17&"','"&H17&"')," -> ('CAMPOS BARRIOS JUANA MILAGROS','UPIS SAN ANDRES MZ. F - LT. 19 - PUEBLO NUEVO - CHINCHA','PUEBLO NUEVO','ZONA: PUEBLO - TECHO PROPIO','956 517 578','15439628','F1'),
A18: 20 | B18: MANUEL YSMAEL YARASCA PURAY | C18: AA.HH. VIRGEN DEL CARMEN MZ A LT 10 - CRUZ BLANCA | D18: CHINCHA ALTA | E18: ZONA: CRUZ BLANCA VIRGEN CARMEN | F18: 950 347 145 | G18: 21519428 | H18: F1 | I18: ="('"&B18&"','"&C18&"','"&D18&"','"&E18&"','"&F18&"','"&G18&"','"&H18&"')," -> ('MANUEL YSMAEL YARASCA PURAY','AA.HH. VIRGEN DEL CARMEN MZ A LT 10 - CRUZ BLANCA','CHINCHA ALTA','ZONA: CRUZ BLANCA VIRGEN CARMEN','950 347 145','21519428','F1'),
A19: 21 | B19: RAMOS AQUIJE EDDY GILMORE | C19: C.P. CONDORILLO ALTO MZ. N LT. 02 - CHINCHA | D19: CHINCHA ALTA | E19: ZONA: CONDORILLO PARTE ALTA | F19: 936 932 786 | G19: 21577420 | H19: F2 | I19: ="('"&B19&"','"&C19&"','"&D19&"','"&E19&"','"&F19&"','"&G19&"','"&H19&"')," -> ('RAMOS AQUIJE EDDY GILMORE','C.P. CONDORILLO ALTO MZ. N LT. 02 - CHINCHA','CHINCHA ALTA','ZONA: CONDORILLO PARTE ALTA','936 932 786','21577420','F2'),
A20: 22 | B20: YATACO GARCIA MOISES | C20: CL. SAN LUIS Nª 139 - CERCADO DE CHINCHA ALTA | D20: CHINCHA ALTA | E20: ZONA: CRUZ BLANCA VIRGEN CARMEN | F20: 944420613 | G20: 21781164 | H20: F1 | I20: ="('"&B20&"','"&C20&"','"&D20&"','"&E20&"','"&F20&"','"&G20&"','"&H20&"')," -> ('YATACO GARCIA MOISES','CL. SAN LUIS Nª 139 - CERCADO DE CHINCHA ALTA','CHINCHA ALTA','ZONA: CRUZ BLANCA VIRGEN CARMEN','944420613','21781164','F1'),
A21: 23 | B21: RIQUELME APOLAYA VDA DE PEREZ GREGORIA ELISA | C21: Av. Melchorita Nº 604 - Grocio Prado | D21: GROCIO PRADO | E21: ZONA: GROCIO - MEJILLONEROS | F21: 956698366 | G21: 21782120 | H21: F1 | I21: ="('"&B21&"','"&C21&"','"&D21&"','"&E21&"','"&F21&"','"&G21&"','"&H21&"')," -> ('RIQUELME APOLAYA VDA DE PEREZ GREGORIA ELISA','Av. Melchorita Nº 604 - Grocio Prado','GROCIO PRADO','ZONA: GROCIO - MEJILLONEROS','956698366','21782120','F1'),
A22: 24 | B22: HERRERA TALLA EDNA CLEMENCIA | C22: AV. UNION SANTA ROSA N110-34 - CRUZ BLANCA | D22: CHINCHA ALTA | E22: ZONA: CRUZ BLANCA CAMPO | F22: 936301541 | G22: 21782325 | H22: F1 | I22: ="('"&B22&"','"&C22&"','"&D22&"','"&E22&"','"&F22&"','"&G22&"','"&H22&"')," -> ('HERRERA TALLA EDNA CLEMENCIA','AV. UNION SANTA ROSA N110-34 - CRUZ BLANCA','CHINCHA ALTA','ZONA: CRUZ BLANCA CAMPO','936301541','21782325','F1'),
A23: 25 | B23: REYES APONTE LUIS MANUEL | C23: CONDORILLO ALTO PRIMERA ENTRADA | D23: CHINCHA ALTA | E23: ZONA: CONDORILLO PARTE BAJA | F23: 936457904 | G23: 21783726 | H23: F1 | I23: ="('"&B23&"','"&C23&"','"&D23&"','"&E23&"','"&F23&"','"&G23&"','"&H23&"')," -> ('REYES APONTE LUIS MANUEL','CONDORILLO ALTO PRIMERA ENTRADA','CHINCHA ALTA','ZONA: CONDORILLO PARTE BAJA','936457904','21783726','F1'),
A24: 26 | B24: CARBAJAL TASAYCO ALBERTO | C24: ENTRADA CONDORILLO PSJ GONZALES PRADA 205 | D24: CHINCHA ALTA | E24: ZONA: CRUZ BLANCA PARTE ALTA oruro | F24: 930 647 571 | G24: 21784064 | H24: F1 | I24: ="('"&B24&"','"&C24&"','"&D24&"','"&E24&"','"&F24&"','"&G24&"','"&H24&"')," -> ('CARBAJAL TASAYCO ALBERTO','ENTRADA CONDORILLO PSJ GONZALES PRADA 205','CHINCHA ALTA','ZONA: CRUZ BLANCA PARTE ALTA oruro','930 647 571','21784064','F1'),
A25: 27 | B25: MAGALLANES ROSSI PAULO FELIX | C25: AV. FATIMA S/N - SUNAMPE | D25: SUNAMPE | E25: ZONA: SUNAMPE – COLEGIO | F25: 942811373 | G25: 21785115 | H25: F1 | I25: ="('"&B25&"','"&C25&"','"&D25&"','"&E25&"','"&F25&"','"&G25&"','"&H25&"')," -> ('MAGALLANES ROSSI PAULO FELIX','AV. FATIMA S/N - SUNAMPE','SUNAMPE','ZONA: SUNAMPE – COLEGIO','942811373','21785115','F1'),
A26: 28 | B26: DE LA CRUZ MENDOZA ROSA ELVIRA | C26: PSJ. 02 DE MAYO Nª 325 - CRUZ BLANCA - CHINCHA ALTA | D26: CHINCHA ALTA | E26: ZONA: CRUZ BLANCA PARTE ALTA oruro | F26: 968 416 588 | G26: 21785244 | H26: F1 | I26: ="('"&B26&"','"&C26&"','"&D26&"','"&E26&"','"&F26&"','"&G26&"','"&H26&"')," -> ('DE LA CRUZ MENDOZA ROSA ELVIRA','PSJ. 02 DE MAYO Nª 325 - CRUZ BLANCA - CHINCHA ALTA','CHINCHA ALTA','ZONA: CRUZ BLANCA PARTE ALTA oruro','968 416 588','21785244','F1'),
A27: 29 | B27: ATUNCAR TASAYCO GILDA ESTHER | C27: SAN PEDRO DE PILPA N514 - SUNAMPE | D27: SUNAMPE | E27: ZONA: SUNAMPE – SAN PILPA | F27: 958608401 | G27: 21786233 | H27: F2 | I27: ="('"&B27&"','"&C27&"','"&D27&"','"&E27&"','"&F27&"','"&G27&"','"&H27&"')," -> ('ATUNCAR TASAYCO GILDA ESTHER','SAN PEDRO DE PILPA N514 - SUNAMPE','SUNAMPE','ZONA: SUNAMPE – SAN PILPA','958608401','21786233','F2'),
A28: 30 | B28: PACHAS MARTINEZ JUANA | C28: Virgen del carmen Mz. I lt. 1 | D28: CHINCHA ALTA | E28: ZONA: CRUZ BLANCA VIRGEN CARMEN | F28: 991 488 690 | G28: 21788723 | H28: F1 | I28: ="('"&B28&"','"&C28&"','"&D28&"','"&E28&"','"&F28&"','"&G28&"','"&H28&"')," -> ('PACHAS MARTINEZ JUANA','Virgen del carmen Mz. I lt. 1','CHINCHA ALTA','ZONA: CRUZ BLANCA VIRGEN CARMEN','991 488 690','21788723','F1'),
A29: 31 | B29: GARCIA DE GARCIA GLADYS | C29: CRUZ BLANCA VIRGEN DEL CARMEN AV TOMA DE CALA | D29: CHINCHA ALTA | E29: ZONA: CRUZ BLANCA PARTE BAJA | F29: 936707747 | G29: 21790332 | H29: F1 | I29: ="('"&B29&"','"&C29&"','"&D29&"','"&E29&"','"&F29&"','"&G29&"','"&H29&"')," -> ('GARCIA DE GARCIA GLADYS','CRUZ BLANCA VIRGEN DEL CARMEN AV TOMA DE CALA','CHINCHA ALTA','ZONA: CRUZ BLANCA PARTE BAJA','936707747','21790332','F1'),
A30: 32 | B30: ELENA EVA LORENZA DURAN BLANCO | C30: CL COLON NRO. PUERTA 279 02 - CERCADO DE CHINCHA ALTA - CHINCHA ALTA | D30: CHINCHA ALTA | E30: ZONA: CHINCHA - AMERICA | F30: 984399198 | G30: 21792478 | H30: F1 | I30: ="('"&B30&"','"&C30&"','"&D30&"','"&E30&"','"&F30&"','"&G30&"','"&H30&"')," -> ('ELENA EVA LORENZA DURAN BLANCO','CL COLON NRO. PUERTA 279 02 - CERCADO DE CHINCHA ALTA - CHINCHA ALTA','CHINCHA ALTA','ZONA: CHINCHA - AMERICA','984399198','21792478','F1'),
A31: 33 | B31: MAGALLANES ORTIZ VICTOR LUIS | C31: CL. EL CARMEN Nª 196, CRUZ BLANCA - CHINCHA ALTA | D31: CHINCHA ALTA | E31: ZONA: CRUZ BLANCA PARTE BAJA | F31: 912074015 | G31: 21794090 | H31: F1 | I31: ="('"&B31&"','"&C31&"','"&D31&"','"&E31&"','"&F31&"','"&G31&"','"&H31&"')," -> ('MAGALLANES ORTIZ VICTOR LUIS','CL. EL CARMEN Nª 196, CRUZ BLANCA - CHINCHA ALTA','CHINCHA ALTA','ZONA: CRUZ BLANCA PARTE BAJA','912074015','21794090','F1'),
A32: 34 | B32: PEREZ HERNANDEZ JORGE ISIDORO | C32: AV. AMERICA N° 533 - INT. 03 - PROGRESO - CHINCHA ALTA | D32: CHINCHA ALTA | E32: ZONA: CHINCHA - PROGRESO | F32: 924422788 | G32: 21794408 | H32: F1 | I32: ="('"&B32&"','"&C32&"','"&D32&"','"&E32&"','"&F32&"','"&G32&"','"&H32&"')," -> ('PEREZ HERNANDEZ JORGE ISIDORO','AV. AMERICA N° 533 - INT. 03 - PROGRESO - CHINCHA ALTA','CHINCHA ALTA','ZONA: CHINCHA - PROGRESO','924422788','21794408','F1'),
A33: 35 | B33: MELO GUERRA ANSELMO | C33: PSJ. SAN MARTIN Nª 474, C.P. MINA DE ORO - SUNAMPE | D33: SUNAMPE | E33: ZONA: SUNAMPE - MINA DE ORO | F33: 904830949 | G33: 21794453 | H33: F1 | I33: ="('"&B33&"','"&C33&"','"&D33&"','"&E33&"','"&F33&"','"&G33&"','"&H33&"')," -> ('MELO GUERRA ANSELMO','PSJ. SAN MARTIN Nª 474, C.P. MINA DE ORO - SUNAMPE','SUNAMPE','ZONA: SUNAMPE - MINA DE ORO','904830949','21794453','F1'),
A34: 36 | B34: DIAZ MAGALLANES SANTOS MANUEL | C34: CRUZ BLANCA VIRGEN DEL CARMEN | D34: CHINCHA ALTA | E34: ZONA: CRUZ BLANCA PARTE BAJA | F34: 925064547 | G34: 21797192 | H34: F1 | I34: ="('"&B34&"','"&C34&"','"&D34&"','"&E34&"','"&F34&"','"&G34&"','"&H34&"')," -> ('DIAZ MAGALLANES SANTOS MANUEL','CRUZ BLANCA VIRGEN DEL CARMEN','CHINCHA ALTA','ZONA: CRUZ BLANCA PARTE BAJA','925064547','21797192','F1'),
A35: 37 | B35: CESPEDES CANELO GLADYS DORA | C35: PSJ. SAN ANTONIO MZ J LT12, ALT. VILLA JULIA - SUNAMPE | D35: SUNAMPE | E35: ZONA: SUNAMPE – VILLA JULIA | F35: 932233737 | G35: 21799902 | H35: F1 | I35: ="('"&B35&"','"&C35&"','"&D35&"','"&E35&"','"&F35&"','"&G35&"','"&H35&"')," -> ('CESPEDES CANELO GLADYS DORA','PSJ. SAN ANTONIO MZ J LT12, ALT. VILLA JULIA - SUNAMPE','SUNAMPE','ZONA: SUNAMPE – VILLA JULIA','932233737','21799902','F1'),
A36: 38 | B36: VILLAVICENCIO GONZALES ORLANDO LUIS | C36: Urb Las Palmeras Mz. D, lote 14, Huaca Grande, Sunampe. | D36: SUNAMPE | E36: ZONA: SUNAMPE – HUACA GRANDE | F36: 955939014 | G36: 21807490 | H36: F1 | I36: ="('"&B36&"','"&C36&"','"&D36&"','"&E36&"','"&F36&"','"&G36&"','"&H36&"')," -> ('VILLAVICENCIO GONZALES ORLANDO LUIS','Urb Las Palmeras Mz. D, lote 14, Huaca Grande, Sunampe.','SUNAMPE','ZONA: SUNAMPE – HUACA GRANDE','955939014','21807490','F1'),
A37: 39 | B37: SALVADOR DE VILLAVICENCIO ANA GLADYS | C37: CONDOMINIO LAS PALMERAS B-29 - C.P. HUACA GRANDE - SUNAMPE | D37: SUNAMPE | E37: ZONA: SUNAMPE – HUACA GRANDE | F37: 955939014 | G37: 21807491 | H37: F1 | I37: ="('"&B37&"','"&C37&"','"&D37&"','"&E37&"','"&F37&"','"&G37&"','"&H37&"')," -> ('SALVADOR DE VILLAVICENCIO ANA GLADYS','CONDOMINIO LAS PALMERAS B-29 - C.P. HUACA GRANDE - SUNAMPE','SUNAMPE','ZONA: SUNAMPE – HUACA GRANDE','955939014','21807491','F1'),
A38: 40 | B38: IBARRA SALAZAR CIRO WILLMAN | C38: URB. JULIO ARBOLEDA MZ. B - LT. 04 - CHINCHA ALTA | D38: SUNAMPE | E38: ZONA: SUNAMPE - MINA DE ORO | F38: 956562524 | G38: 21807868 | H38: F1 | I38: ="('"&B38&"','"&C38&"','"&D38&"','"&E38&"','"&F38&"','"&G38&"','"&H38&"')," -> ('IBARRA SALAZAR CIRO WILLMAN','URB. JULIO ARBOLEDA MZ. B - LT. 04 - CHINCHA ALTA','SUNAMPE','ZONA: SUNAMPE - MINA DE ORO','956562524','21807868','F1'),
A39: 41 | B39: ATUNCAR DE LA CRUZ LUZ MARLENE | C39: Sunampe, Av. Huascar (Casa de pandora 02) | D39: SUNAMPE | E39: ZONA: SUNAMPE – SAN IGNACIO | F39: 965696392 | G39: 21808481 | H39: F1 | I39: ="('"&B39&"','"&C39&"','"&D39&"','"&E39&"','"&F39&"','"&G39&"','"&H39&"')," -> ('ATUNCAR DE LA CRUZ LUZ MARLENE','Sunampe, Av. Huascar (Casa de pandora 02)','SUNAMPE','ZONA: SUNAMPE – SAN IGNACIO','965696392','21808481','F1'),
A40: 42 | B40: AGUILAR HERNANDEZ DE MUCHAYPIÑA MARIA ELIZABETH | C40: URB. LEON DE VIVERO MZ. 04 LT. 07 - PUEBLO NUEVO | D40: PUEBLO NUEVO | E40: ZONA: PUEBLO - SALVADOR | F40: 956 791 396 | G40: 21810864 | H40: F1 | I40: ="('"&B40&"','"&C40&"','"&D40&"','"&E40&"','"&F40&"','"&G40&"','"&H40&"')," -> ('AGUILAR HERNANDEZ DE MUCHAYPIÑA MARIA ELIZABETH','URB. LEON DE VIVERO MZ. 04 LT. 07 - PUEBLO NUEVO','PUEBLO NUEVO','ZONA: PUEBLO - SALVADOR','956 791 396','21810864','F1'),
...

Sheet análisis
B6: DISTRITOS | C6: TOTAL
B7: CHINCHA ALTA | C7: 221
B8: GROCIO PRADO | C8: 43
B9: PUEBLO NUEVO | C9: 81
B10: SUNAMPE | C10: 358
B11: TAMBO DE MORA | C11: 16
B12: Total general | C12: 719
E18: 30
B20: DISTRITOS | C20: TOTAL | D20: % | E20: CANASTAS % | F20: CANASTAS
B21: CHINCHA ALTA | C21: 221 | D21: =(C21/$C$26)*100 -> 30.737135 | E21: =(D21*$E$18)/100 -> 9.2211405 | F21: 9
B22: GROCIO PRADO | C22: 43 | D22: =(C22/$C$26)*100 -> 5.9805285 | E22: =(D22*$E$18)/100 -> 1.7941586 | F22: 2
B23: PUEBLO NUEVO | C23: 81 | D23: =(C23/$C$26)*100 -> 11.265647 | E23: =(D23*$E$18)/100 -> 3.379694 | F23: 3
B24: SUNAMPE | C24: 358 | D24: =(C24/$C$26)*100 -> 49.791377 | E24: =(D24*$E$18)/100 -> 14.937413 | F24: 14
B25: TAMBO DE MORA | C25: 16 | D25: =(C25/$C$26)*100 -> 2.2253129 | E25: =(D25*$E$18)/100 -> 0.66759388 | F25: 2
C26: =SUM(C21:C25) -> 719 | D26: =SUM(D21:D25) -> 100 | E26: =SUM(E21:E25) -> 30 | F26: =SUM(F21:F25) -> 30
E28: 30 | F28: 100
E29: ? | F29: 30
